<?xml version="1.0"?>
<sdf version="1.4">
  <model name="refrigerator">
    <static>false</static>
   <link name="body">
      <inertial>
        <mass>30</mass>
        <inertia>
          <ixx>1</ixx>
          <ixy>0</ixy>
          <ixz>0</ixz>
          <iyy>1</iyy>
          <iyz>0</iyz>
          <izz>0.3</izz>
        </inertia>
      </inertial>
      <visual name="visual_body">
        <geometry>
          <mesh>
            <uri>model://refrigerator/meshes/refrigerator_body.dae</uri>
          </mesh>
        </geometry>
      </visual>

      <collision name="body_1">
	<pose>-0.008 0 0.015 0 0 0</pose>
        <geometry>
	<box><size>0.49 0.55 0.03</size></box>
        </geometry>
      </collision>

      <collision name="body_2">
	<pose>-0.008 0.275 0.786 0 0 0</pose>
        <geometry>
	<box><size>0.49 0.005 1.566</size></box>
        </geometry>
      </collision>

      <collision name="body_3">
	<pose>-0.008 -0.275 0.783 0 0 0</pose>
        <geometry>
	<box><size>0.49 0.005 1.566</size></box>
        </geometry>
      </collision>

      <collision name="body_4">
	<pose>-0.253 0 0.783 0 0 0</pose>
        <geometry>
	<box><size>0.004 0.55 1.566</size></box>
        </geometry>
      </collision>

      <collision name="body_5">
	<pose>-0.008 0 0.529 0 0 0</pose>
        <geometry>
	<box><size>0.49 0.55 0.015</size></box>
        </geometry>
      </collision>

      <collision name="body_6">
	<pose>-0.008 0 0.9124 0 0 0</pose>
        <geometry>
	<box><size>0.49 0.55 0.015</size></box>
        </geometry>
      </collision>

      <collision name="body_7">
	<pose>-0.008 0 1.1464 0 0 0</pose>
        <geometry>
	<box><size>0.49 0.55 0.015</size></box>
        </geometry>
      </collision>

      <collision name="body_8">
	<pose>0.022 0 1.55 0 0 0</pose>
        <geometry>
	<box><size>0.55 0.55 0.036</size></box>
        </geometry>
      </collision>

    </link>


<link name="down_door">
      <inertial>
        <mass>0.8</mass>
        <inertia>
          <ixx>1</ixx>
          <ixy>0</ixy>
          <ixz>0</ixz>
          <iyy>1</iyy>
          <iyz>0</iyz>
          <izz>1</izz>
        </inertia>
      </inertial>
	<pose>0.24 0 0.03 0 0 0</pose>
	<visual name="visual_down_door">
	<pose>0 0 0 0 0 0</pose>
        <geometry>
          <mesh>
            <uri>model://refrigerator/meshes/refrigerator_down_door.dae</uri>
	    <scale>1 1 1.1</scale>
          </mesh>
        </geometry>
      </visual>

      <collision name="dd">
	<pose>0 0 0.44 0 0 0</pose>
        <geometry>
	<box><size>0.06 0.55 0.88</size></box>
        </geometry>
      </collision>

</link>

<link name="up_door">
      <inertial>
        <mass>0.8</mass>
        <inertia>
          <ixx>1</ixx>
          <ixy>0</ixy>
          <ixz>0</ixz>
          <iyy>1</iyy>
          <iyz>0</iyz>
          <izz>1</izz>
        </inertia>
      </inertial>
	<pose>0.24 0 0.92 0 0 0</pose>
	<visual name="visual_up_door">
	<pose>-0.004 0.012 0 0 0 0</pose>
        <geometry>
          <mesh>
            <uri>model://refrigerator/meshes/refrigerator_up_door.dae</uri>
          </mesh>
        </geometry>
      </visual>

      <collision name="ud">
	<pose>0 0 0.3 0 0 0</pose>
        <geometry>
	<box><size>0.06 0.55 0.6</size></box>
        </geometry>
      </collision>

</link>

      <joint type="revolute" name="up_door_joint">
        <pose>0 0.275 0 0 0 0</pose>
        <child>up_door</child>
        <parent>body</parent>
        <axis>
    		<limit>
      			<upper>2</upper>
      			<lower>0</lower>
    		</limit>
          <xyz>0 0 1</xyz>
          <dynamics>
            <damping>10</damping>
          </dynamics>
        </axis>
      </joint>

      <joint type="revolute" name="down_door_joint">
        <pose>0 0.275 0 0 0 0</pose>
        <child>down_door</child>
        <parent>body</parent>
        <axis>
    		<limit>
      			<upper>2</upper>
      			<lower>0</lower>
    		</limit>
          <xyz>0 0 1</xyz>
          <dynamics>
            <damping>10</damping>
          </dynamics>
        </axis>
      </joint>

  </model>
</sdf>
