<?xml version="1.0"?>
<sdf version="1.4">
  <model name="closet">
    <static>false</static>

    <link name="body">
      <inertial>
        <mass>50</mass>
        <inertia>
          <ixx>1</ixx>
          <ixy>0</ixy>
          <ixz>0</ixz>
          <iyy>1</iyy>
          <iyz>0</iyz>
          <izz>0.7</izz>
        </inertia>
      </inertial>
      <visual name="visual">
<pose>0.0013 -0.013 0 0 0 0</pose>
        <geometry>
          <mesh>
            <uri>model://closet/meshes/closet_body.dae</uri>
          </mesh>
        </geometry>
      </visual>

      <collision name="body_1">
<pose>0 0 0.166 0 0 0</pose>
        <geometry>
<box><size>2.544 0.754 0.332</size></box>
        </geometry>
      </collision>

      <collision name="body_2">
<pose>1.253 0 0.967 0 0 0</pose>
        <geometry>
<box><size>0.037 0.754 1.934</size></box>
        </geometry>
      </collision>

      <collision name="body_3">
<pose>-1.253 0 0.967 0 0 0</pose>
        <geometry>
<box><size>0.037 0.754 1.934</size></box>
        </geometry>
      </collision>

      <collision name="body_4">
<pose>-0.425 0 0.967 0 0 0</pose>
        <geometry>
<box><size>0.074 0.754 1.934</size></box>
        </geometry>
      </collision>

      <collision name="body_5">
<pose>0 0.3585 0.967 0 0 0</pose>
        <geometry>
<box><size>2.544 0.037 1.934</size></box>
        </geometry>
      </collision>

      <collision name="body_6">
<pose>-0.848 0 0.6085 0 0 0</pose>
        <geometry>
<box><size>0.774 0.754 0.037</size></box>
        </geometry>
      </collision>

      <collision name="body_7">
<pose>-0.848 0 0.9055 0 0 0</pose>
        <geometry>
<box><size>0.774 0.754 0.037</size></box>
        </geometry>
      </collision>

      <collision name="body_8">
<pose>-0.848 0 1.2015 0 0 0</pose>
        <geometry>
<box><size>0.774 0.754 0.037</size></box>
        </geometry>
      </collision>

      <collision name="body_9">
<pose>-0.848 0 1.4975 0 0 0</pose>
        <geometry>
<box><size>0.774 0.754 0.037</size></box>
        </geometry>
      </collision>

      <collision name="body_10">
<pose>-0.848 0 1.7935 0 0 0</pose>
        <geometry>
<box><size>0.774 0.754 0.037</size></box>
        </geometry>
      </collision>

      <collision name="body_11">
<pose>0 0 1.9155 0 0 0</pose>
        <geometry>
<box><size>2.544 0.754 0.037</size></box>
        </geometry>
      </collision>
    </link>

<link name="left_door">
      <inertial>
        <mass>2</mass>
        <inertia>
          <ixx>1</ixx>
          <ixy>0</ixy>
          <ixz>0</ixz>
          <iyy>1</iyy>
          <iyz>0</iyz>
          <izz>1</izz>
        </inertia>
      </inertial>
<pose>0.848 -0.414 0.019 0 0 0</pose>
      <visual name="visual">
<pose>-0.0185 0 0 0 0 0</pose>
        <geometry>
          <mesh>
            <uri>model://closet/meshes/closet_left_door.dae</uri>
          </mesh>
        </geometry>
      </visual>

      <collision name="door">
<pose>0 0 0.948 0 0 0</pose>
        <geometry>
<box><size>0.848 0.025 1.896</size></box>
        </geometry>
      </collision>
</link>

<link name="right_door">
      <inertial>
        <mass>2</mass>
        <inertia>
          <ixx>1</ixx>
          <ixy>0</ixy>
          <ixz>0</ixz>
          <iyy>1</iyy>
          <iyz>0</iyz>
          <izz>1</izz>
        </inertia>
      </inertial>
<pose>0 -0.414 0.019 0 0 0</pose>
      <visual name="visual">
<pose>0.006 0.8475 0 0 0 0</pose>
        <geometry>
          <mesh>
            <uri>model://closet/meshes/closet_right_door.dae</uri>
          </mesh>
        </geometry>
      </visual>
      <collision name="door">
<pose>0 0 0.949 0 0 0</pose>
        <geometry>
<box><size>0.848 0.025 1.898</size></box>
        </geometry>
      </collision>
</link>

      <joint type="revolute" name="left_door_joint">
        <pose>0.424 0 0 0 0 0</pose>
        <child>left_door</child>
        <parent>body</parent>
        <axis>
    		<limit>
      			<upper>2</upper>
      			<lower>0</lower>
    		</limit>
          <xyz>0 0 1</xyz>
          <dynamics>
            <damping>10</damping>
          </dynamics>
        </axis>
      </joint>

      <joint type="revolute" name="right_door_joint">
        <pose>-0.424 0 0 0 0 0</pose>
        <child>right_door</child>
        <parent>body</parent>
        <axis>
    		<limit>
      			<upper>0</upper>
      			<lower>-2</lower>
    		</limit>
          <xyz>0 0 1</xyz>
          <dynamics>
            <damping>10</damping>
          </dynamics>
        </axis>
      </joint>

  </model>
</sdf>
