<?xml version="1.0" encoding="utf-8" ?>
<!-- =================================================================================== -->
<!-- |    This document was autogenerated by xacro from /home/gw/catkin_ws/src/kejia/kejia_simulator/kejia_description/urdf/kejia.xacro | -->
<!-- |    EDITING THIS FILE BY HAND IS NOT RECOMMENDED                                 | -->
<!-- =================================================================================== -->
<robot name="kejia">
    <material name="black">
        <color rgba="0.0 0.0 0.0 1.0" />
    </material>
    <material name="blue">
        <color rgba="0.0 0.0 0.8 1.0" />
    </material>
    <material name="green">
        <color rgba="0.0 0.8 0.0 1.0" />
    </material>
    <material name="grey">
        <color rgba="0.2 0.2 0.2 1.0" />
    </material>
    <material name="orange">
        <color rgba="1.0 0.423529411765 0.0392156862745 1.0" />
    </material>
    <material name="brown">
        <color rgba="0.870588235294 0.811764705882 0.764705882353 1.0" />
    </material>
    <material name="red">
        <color rgba="0.8 0.0 0.0 1.0" />
    </material>
    <material name="white">
        <color rgba="1.0 1.0 1.0 1.0" />
    </material>
    <!-- see https://secure.wikimedia.org/wikipedia/en/wiki/List_of_moment_of_inertia_tensors -->
    <!-- base_link -->
    <link name="base_link" />
    <!-- Chassis -->
    <joint name="base_link_chassis_joint" type="fixed">
        <origin rpy="0 0 0" xyz="0 0 0.15" />
        <parent link="base_link" />
        <child link="chassis" />
    </joint>
    <link name="chassis">
        <visual name="chassis_visual">
            <geometry name="chassis_geometry">
                <box size="0.5 0.5 0.2" />
            </geometry>
        </visual>
        <collision name="chassis_collision">
            <geometry>
                <box size="0.5 0.5 0.2" />
            </geometry>
        </collision>

        <inertial>
            <mass value="15.0" />
            <origin xyz="0 0 0" />
            <inertia ixx="0.362499855" ixy="0.0" ixz="0.0" iyy="0.362499855" iyz="0.0" izz="0.62499975" />
        </inertial>

    </link>
    <joint name="chassis_laser_joint" type="fixed">
        <origin rpy="0 0 0" xyz="0.23 0 0.16" />
        <parent link="chassis" />
        <child link="laser_link" />
    </joint>
    <link name="laser_link">
        <visual name="laser_link_visual">
            <origin rpy="0 0 0" xyz="-0.025 0 -0.02" />
            <geometry name="chassis_geometry">
                <mesh filename="package://kejia_description/sdf/hokuyo/meshes/hokuyo.dae" />
            </geometry>
        </visual>
        <collision name="laser_link_collision">
            <origin rpy="0 0 0" xyz="-0.025 0 -0.02" />
            <geometry>
                <box size="0.05 0.05 0.08" />
            </geometry>
        </collision>

        <inertial>
            <mass value="0.1" />
            <inertia ixx="0.03" iyy="0.03" izz="0.03" ixy="0.0" ixz="0.0" iyz="0.0" />
        </inertial>

    </link>
    <gazebo reference="chassis">
        <material value="Gazebo/White" />
    </gazebo>
    <gazebo reference="laser_link">
        <sensor name="head_hokuyo_sensor" type="ray">
            <pose>0 0 0 0 0 0</pose>
            <always_on>1</always_on>
            <update_rate>30</update_rate>
            <visualize>true</visualize>
            <ray>
                <scan>
                    <horizontal>
                        <!-- The URG-04LX-UG01  has  683 steps with 0.35139 Degree resolution -->
                        <resolution>1</resolution>
                        <max_angle>2.0944</max_angle>
                        <!-- 120 Degree -->
                        <min_angle>-2.0944</min_angle>
                        <!-- -120 Degree -->
                        <samples>683</samples>
                    </horizontal>
                </scan>
                <range>
                    <min>0.10</min>
                    <max>140.0</max>
                    <resolution>0.01</resolution>
                </range>
                <noise>
                    <type>gaussian</type>
                    <!-- Noise parameters based on published spec for Hokuyo laser
               achieving "+-30mm" accuracy at range < 10m.  A mean of 0.0m and
               stddev of 0.01m will put 99.7% of samples within 0.03m of the true
               reading. -->
                    <mean>0.0</mean>
                    <stddev>0.01</stddev>
                </noise>
            </ray>
            <plugin filename="libgazebo_ros_laser.so" name="gazebo_ros_base_hokuyo_controller">
                <topicName>/scan</topicName>
                <frameName>laser_link</frameName>
            </plugin>
        </sensor>
        <material value="Gazebo/Black" />
    </gazebo>
    <!-- Wheel -->
    <joint name="left_wheel_joint" type="continuous">
        <origin rpy="1.57079632679 0 0" xyz="0 0.20 0.09" />
        <parent link="base_link" />
        <child link="left_wheel" />
        <axis xyz="0 0 -1" />
        <limit effort="100" velocity="10.0" />
        <joint_properties damping="0.0" friction="0.0" />
    </joint>
    <link name="left_wheel">
        <visual name="left_wheel_visual">
            <origin rpy="0 0 0" xyz="0 0 0" />
            <geometry name="{name}_wheel_geometry">
                <cylinder length="0.05" radius="0.09" />
            </geometry>
            <material name="orange" />
        </visual>
        <collision>
            <origin rpy="0 0 0" xyz="0 0 0" />
            <geometry>
                <cylinder length="0.05" radius="0.09" />
            </geometry>
        </collision>

        <inertial>
            <mass value="15" />
            <origin xyz="0 0 0" />
            <inertia ixx="0.4" ixy="0" ixz="0" iyy="0.4" iyz="0" izz="0.2" />
        </inertial>

    </link>
    <gazebo reference="left_wheel">
        <!-- <mu1 value="1.0"/>
    <mu2 value="1.0"/>
    <kp value="10000000.0"/>
    <kd value="1.0"/> -->
        <mu1>100000</mu1>
        <mu2>100000</mu2>
        <kp>100000000.0</kp>
        <kd>1.0</kd>
        <fdir1 value="0 0 1" />
        <material>Gazebo/Grey</material>
        <turnGravityOff>false</turnGravityOff>
    </gazebo>
    <!-- Wheel -->
    <joint name="right_wheel_joint" type="continuous">
        <origin rpy="1.57079632679 0 0" xyz="0 -0.20 0.09" />
        <parent link="base_link" />
        <child link="right_wheel" />
        <axis xyz="0 0 -1" />
        <limit effort="100" velocity="10.0" />
        <joint_properties damping="0.0" friction="0.0" />
    </joint>
    <link name="right_wheel">
        <visual name="right_wheel_visual">
            <origin rpy="0 0 0" xyz="0 0 0" />
            <geometry name="{name}_wheel_geometry">
                <cylinder length="0.05" radius="0.09" />
            </geometry>
            <material name="orange" />
        </visual>
        <collision>
            <origin rpy="0 0 0" xyz="0 0 0" />
            <geometry>
                <cylinder length="0.05" radius="0.09" />
            </geometry>
        </collision>

        <inertial>
            <mass value="15" />
            <origin xyz="0 0 0" />
            <inertia ixx="0.4" ixy="0" ixz="0" iyy="0.4" iyz="0" izz="0.2" />
        </inertial>

    </link>
    <gazebo reference="right_wheel">
        <!-- <mu1 value="1.0"/>
    <mu2 value="1.0"/>
    <kp value="10000000.0"/>
    <kd value="1.0"/> -->
        <mu1>100000</mu1>
        <mu2>100000</mu2>
        <kp>100000000.0</kp>
        <kd>1.0</kd>
        <fdir1 value="0 0 1" />
        <material>Gazebo/Grey</material>
        <turnGravityOff>false</turnGravityOff>
    </gazebo>
    <!-- Wheel -->
    <joint name="back_wheel_joint" type="fixed">
        <origin rpy="1.57079632679 0 0" xyz="-0.15 0.0 0.06" />
        <parent link="base_link" />
        <child link="back_wheel" />
    </joint>
    <link name="back_wheel">
        <visual name="back_wheel_visual">
            <origin rpy="0 0 0" xyz="0 0 0" />
            <geometry name="{name}_wheel_geometry">
                <sphere radius="0.06" />
            </geometry>
            <material name="orange" />
        </visual>
        <collision>
            <origin rpy="0 0 0" xyz="0 0 0" />
            <geometry>
                <sphere radius="0.06" />
            </geometry>
        </collision>

        <inertial>
            <mass value="5" />
            <origin xyz="0 0 0" />
            <inertia ixx="0.4" ixy="0.0" ixz="0.0" iyy="0.4" iyz="0.0" izz="0.4" />
        </inertial>

    </link>
    <gazebo reference="back_wheel">
        <mu1 value="0" />
        <mu2 value="0" />
        <kp value="10000000.0" />
        <kd value="1.0" />
        <fdir1 value="1 0 0" />
        <material>Gazebo/Grey</material>
        <turnGravityOff>false</turnGravityOff>
    </gazebo>
    <!-- Wheel -->
    <joint name="front_wheel_joint" type="fixed">
        <origin rpy="1.57079632679 0 0" xyz="0.15 0.0 0.06" />
        <parent link="base_link" />
        <child link="front_wheel" />
    </joint>
    <link name="front_wheel">
        <visual name="front_wheel_visual">
            <origin rpy="0 0 0" xyz="0 0 0" />
            <geometry name="{name}_wheel_geometry">
                <sphere radius="0.06" />
            </geometry>
            <material name="orange" />
        </visual>
        <collision>
            <origin rpy="0 0 0" xyz="0 0 0" />
            <geometry>
                <sphere radius="0.06" />
            </geometry>
        </collision>

        <inertial>
            <mass value="5" />
            <origin xyz="0 0 0" />
            <inertia ixx="0.4" ixy="0.0" ixz="0.0" iyy="0.4" iyz="0.0" izz="0.4" />
        </inertial>

    </link>
    <gazebo reference="front_wheel">
        <mu1 value="0" />
        <mu2 value="0" />
        <kp value="10000000.0" />
        <kd value="1.0" />
        <fdir1 value="1 0 0" />
        <material>Gazebo/Grey</material>
        <turnGravityOff>false</turnGravityOff>
    </gazebo>
    <!-- Ev -->
    <joint name="chassis_ev_joint" type="fixed">
        <origin rpy="0 0 0" xyz="0 0 0.10" />
        <parent link="chassis" />
        <child link="ev" />
    </joint>
    <link name="ev">

        <inertial>
            <mass value="0.1" />
            <origin rpy="0 0 0" xyz="0 0 0" />
            <inertia ixx="0" ixy="0" ixz="0" iyy="0" iyz="0" izz="0" />
        </inertial>

        <visual name="ev_visual">
            <origin rpy="0 0 0" xyz="0     0       0.5" />
            <geometry>
                <cylinder length="1.0" radius=".01" />
            </geometry>
            <material name="black" />
        </visual>
        <collision name="ev_collision">
            <origin rpy="0 0 0" xyz="0     0       0.5" />
            <geometry>
                <cylinder length="1.0" radius=".01" />
            </geometry>
        </collision>
        <visual name="ev_visual2">
            <origin rpy="0 0 0" xyz="-0.08     0       0.5" />
            <geometry>
                <cylinder length="1.0" radius=".01" />
            </geometry>
            <material name="black" />
        </visual>
        <collision name="ev_collision2">
            <origin rpy="0 0 0" xyz="-0.08     0       0.5" />
            <geometry>
                <cylinder length="1.0" radius=".01" />
            </geometry>
        </collision>
        <visual name="ev_visual3">
            <origin rpy="0 0 0" xyz="-0.04   0      1.0" />
            <geometry>
                <box size=".152 .09 .02" />
            </geometry>
            <material name="black" />
        </visual>
        <collision name="ev_collision3">
            <origin rpy="0 0 0" xyz="-0.04   0      1.0" />
            <geometry>
                <box size=".152 .09 .02" />
            </geometry>
        </collision>
    </link>
    <gazebo reference="ev">
        <material value="Gazebo/Black" />
    </gazebo>
    <!-- kejia_support -->
    <joint name="ev_support_joint" type="prismatic">
        <parent link="ev" />
        <child link="support" />
        <origin rpy="0 0 0" xyz="0 0 0.95" />
        <axis xyz="0 0 1" />
        <limit effort="100.0" lower="-0.7" upper="0.0" velocity="0.3" />
    </joint>
    <link name="support">

        <inertial>
            <mass value="0.1" />
            <origin rpy="0 0 0" xyz="0 0 0" />
            <inertia ixx="0" ixy="0" ixz="0" iyy="0" iyz="0" izz="0" />
        </inertial>

        <collision name="support_collision1">
            <origin rpy="0 0 0" xyz="0.04 0 0" />
            <geometry>
                <box size="0.12 0.1 0.05" />
            </geometry>
        </collision>
        <visual name="support_visual1">
            <origin rpy="0 0 0" xyz="0.04 0 0" />
            <geometry>
                <box size="0.12 0.1 0.05" />
            </geometry>
            <material name="red" />
        </visual>
        <collision name="support_collision2">
            <origin rpy="0 0 0" xyz="0.125 0 0.075" />
            <geometry>
                <box size="0.05 0.1 0.20" />
            </geometry>
        </collision>
        <visual name="support_visual2">
            <origin rpy="0 0 0" xyz="0.125 0 0.075" />
            <geometry>
                <box size="0.05 0.1 0.20" />
            </geometry>
            <material name="red" />
        </visual>
        <collision name="support_collision3">
            <origin rpy="0 0 0" xyz="0.20 0 0.15" />
            <geometry>
                <box size="0.1 0.1 0.05" />
            </geometry>
        </collision>
        <visual name="support_visual3">
            <origin rpy="0 0 0" xyz="0.20 0 0.15" />
            <geometry>
                <box size="0.1 0.1 0.05" />
            </geometry>
            <material name="red" />
        </visual>
    </link>
    <joint name="neck_pan_joint" type="revolute">
        <parent link="support" />
        <child link="head_pan" />
        <origin rpy="0 0 0" xyz="0.225 0 0.175" />
        <axis xyz="0 0 1" />
        <limit effort="10.0" lower="-1.7" upper="1.7" velocity="3.0" />
    </joint>
    <link name="head_pan">

        <inertial>
            <mass value="0.1" />
            <origin rpy="0 0 0" xyz="0 0 0" />
            <inertia ixx="0" ixy="0" ixz="0" iyy="0" iyz="0" izz="0" />
        </inertial>

        <collision name="head_pan_collision">
            <origin rpy="0 0 0" xyz="0 0 0.05" />
            <geometry>
                <box size="0.05 0.05 0.10" />
            </geometry>
        </collision>
        <visual name="head_pan_visual">
            <origin rpy="0 0 0" xyz="0 0 0.05" />
            <geometry>
                <box size="0.05 0.05 0.10" />
            </geometry>
            <material name="green" />
        </visual>
    </link>
    <joint name="neck_tilt_joint" type="revolute">
        <parent link="head_pan" />
        <child link="head_tilt" />
        <origin rpy="0 0 0" xyz="0 0 0.10" />
        <axis xyz="0 -1 0" />
        <limit effort="10.0" lower="-1.7" upper="1.7" velocity="3.0" />
    </joint>
    <link name="head_tilt">

        <inertial>
            <mass value="0.1" />
            <origin rpy="0 0 0" xyz="0 0 0" />
            <inertia ixx="0" ixy="0" ixz="0" iyy="0" iyz="0" izz="0" />
        </inertial>

        <collision name="head_tilt_collision">
            <origin rpy="1.57 0 0" xyz="0 0 0.025" />
            <geometry>
                <cylinder length="0.1" radius=".025" />
            </geometry>
        </collision>
        <visual name="head_tilt_visual">
            <origin rpy="1.57 0 0" xyz="0 0 0.025" />
            <geometry>
                <cylinder length="0.1" radius=".025" />
            </geometry>
            <material name="green" />
        </visual>
        <collision name="head_tilt_collision1">
            <origin rpy="0 0 0" xyz="0 0 0.045" />
            <geometry>
                <box size="0.05 0.10 0.01" />
            </geometry>
        </collision>
        <visual name="head_tilt_visual1">
            <origin rpy="0 0 0" xyz="0 0 0.045" />
            <geometry>
                <box size="0.05 0.10 0.01" />
            </geometry>
            <material name="green" />
        </visual>
    </link>
    <gazebo reference="support">
        <material value="Gazebo/Red" />
    </gazebo>
    <gazebo reference="head_pan">
        <material value="Gazebo/Green" />
    </gazebo>
    <gazebo reference="head_tilt">
        <material value="Gazebo/Blue" />
    </gazebo>
    <!-- Kinect -->
    <joint name="head_tilt_head_kinect_joint" type="fixed">
        <origin rpy="0 0 0" xyz="0 0 0.086" />
        <parent link="head_tilt" />
        <child link="head_kinect" />
    </joint>
    <link name="head_kinect">
        <collision name="head_kinect_collision">
            <origin rpy="0 0 0" xyz="0.03 0 0.01" />
            <geometry>
                <box size="0.073000 0.276000 0.072000" />
            </geometry>
        </collision>
        <visual name="head_kinect_visual">
            <origin rpy="0 0 0" xyz="0.03 0 0.01" />
            <geometry>
                <mesh filename="package://kejia_description/sdf/kinect/meshes/kinect.dae" />
            </geometry>
        </visual>

        <inertial>
            <mass value="0.1" />
            <inertia ixx="0.03" iyy="0.03" izz="0.03" ixy="0.0" ixz="0.0" iyz="0.0" />
        </inertial>

    </link>
    <gazebo reference="head_kinect">
        <sensor name="head_kinect_frame_sensor" type="depth">
            <always_on>true</always_on>
            <update_rate>20.0</update_rate>
            <camera>
                <horizontal_fov>0.994837673637</horizontal_fov>
                <image>
                    <format>R8G8B8</format>
                    <width>640</width>
                    <height>480</height>
                </image>
                <clip>
                    <near>0.01</near>
                    <far>5</far>
                </clip>
            </camera>
            <plugin filename="libgazebo_ros_openni_kinect.so" name="head_kinect_frame_controller">
                <alwaysOn>true</alwaysOn>
                <updateRate>20.0</updateRate>
                <cameraName>head_kinect</cameraName>
                <imageTopicName>head_kinect/rgb/image_raw</imageTopicName>
                <cameraInfoTopicName>head_kinect/rgb/camera_info</cameraInfoTopicName>
                <depthImageTopicName>head_kinect/depth/image_raw</depthImageTopicName>
                <depthImageCameraInfoTopicName>head_kinect/depth/camera_info</depthImageCameraInfoTopicName>
                <pointCloudTopicName>head_kinect/rgb/points</pointCloudTopicName>
                <frameName>head_kinect_optical_frame</frameName>
                <pointCloudCutoff>0.5</pointCloudCutoff>
                <distortionK1>0.00000001</distortionK1>
                <distortionK2>0.00000001</distortionK2>
                <distortionK3>0.00000001</distortionK3>
                <distortionT1>0.00000001</distortionT1>
                <distortionT2>0.00000001</distortionT2>
                <CxPrime>0</CxPrime>
                <Cx>0</Cx>
                <Cy>0</Cy>
                <focalLength>0</focalLength>
                <hackBaseline>0</hackBaseline>
            </plugin>
        </sensor>
    </gazebo>
    <!-- kejia_arm -->
    <joint name="support_arm_joint" type="fixed">
        <parent link="support" />
        <child link="arm_base" />
        <origin rpy="0 0 0" xyz="0.215 0 0.125" />
    </joint>
    <link name="arm_base">

        <inertial>
            <mass value="0.01" />
            <origin rpy="0 0 0" xyz="0 0 0" />
            <inertia ixx="0" ixy="0" ixz="0" iyy="0" iyz="0" izz="0" />
        </inertial>

        <collision name="arm_collision">
            <origin rpy="0 0 0" xyz="0 0 -0.025" />
            <geometry>
                <cylinder length="0.05" radius="0.035" />
            </geometry>
        </collision>
        <visual name="arm_visual">
            <origin rpy="0 0 0" xyz="0 0 -0.025" />
            <geometry>
                <cylinder length="0.05" radius="0.035" />
            </geometry>
        </visual>
        <visual>
            <origin rpy="0 0 0" xyz="0 0 -0.055" />
            <geometry>
                <cylinder length="0.01" radius="0.036" />
            </geometry>
        </visual>
    </link>
    <joint name="arm_base_arm_lr_joint" type="revolute">
        <parent link="arm_base" />
        <child link="arm_lr" />
        <origin rpy="0 0 0" xyz="0 0 -0.05" />
        <axis xyz="0 0 1" />
        <limit effort="10.0" lower="-2.8" upper="2.8" velocity="2.0" />
    </joint>
    <link name="arm_lr">

        <inertial>
            <mass value="0.01" />
            <origin rpy="0 0 0" xyz="0 0 0" />
            <inertia ixx="0" ixy="0" ixz="0" iyy="0" iyz="0" izz="0" />
        </inertial>

        <collision>
            <origin rpy="0 0 0" xyz="0 0 -0.04" />
            <geometry>
                <cylinder length="0.08" radius="0.025" />
            </geometry>
        </collision>
        <visual>
            <origin rpy="0 0 0" xyz="0 0 -0.04" />
            <geometry>
                <cylinder length="0.08" radius="0.025" />
            </geometry>
        </visual>
    </link>
    <joint name="arm_lr_arm_ud1_joint" type="revolute">
        <parent link="arm_lr" />
        <child link="arm_ud1" />
        <origin rpy="0 0 0" xyz="0 0 -0.095" />
        <axis xyz="0 -1 0" />
        <limit effort="10.0" lower="-2.8" upper="2.8" velocity="2.0" />
    </joint>
    <link name="arm_ud1">

        <inertial>
            <mass value="0.01" />
            <origin rpy="0 0 0" xyz="0 0 0" />
            <inertia ixx="0" ixy="0" ixz="0" iyy="0" iyz="0" izz="0" />
        </inertial>

        <collision>
            <origin rpy="1.57079 0 0" xyz="0 0 0" />
            <geometry>
                <cylinder length="0.06" radius="0.03" />
            </geometry>
        </collision>
        <visual>
            <origin rpy="1.57079 0 0" xyz="0 0 0" />
            <geometry>
                <cylinder length="0.06" radius="0.03" />
            </geometry>
        </visual>
        <collision name="arm_collision">
            <origin rpy="0 0 0" xyz="0 0 -0.105" />
            <geometry>
                <cylinder length="0.18" radius="0.025" />
            </geometry>
        </collision>
        <visual name="arm_visual">
            <origin rpy="0 0 0" xyz="0 0 -0.105" />
            <geometry>
                <cylinder length="0.18" radius="0.025" />
            </geometry>
        </visual>
    </link>
    <joint name="arm_ud1_arm_ud2_joint" type="revolute">
        <parent link="arm_ud1" />
        <child link="arm_ud2" />
        <origin rpy="0 0 0" xyz="0 0 -0.21" />
        <axis xyz="0 -1 0" />
        <limit effort="10.0" lower="-2.8" upper="2.8" velocity="2.0" />
    </joint>
    <link name="arm_ud2">

        <inertial>
            <mass value="0.01" />
            <origin rpy="0 0 0" xyz="0 0 0" />
            <inertia ixx="0" ixy="0" ixz="0" iyy="0" iyz="0" izz="0" />
        </inertial>

        <collision>
            <origin rpy="1.57079 0 0" xyz="0 0 0" />
            <geometry>
                <cylinder length="0.06" radius="0.03" />
            </geometry>
        </collision>
        <visual>
            <origin rpy="1.57079 0 0" xyz="0 0 0" />
            <geometry>
                <cylinder length="0.06" radius="0.03" />
            </geometry>
        </visual>
        <collision name="arm_collision">
            <origin rpy="0 0 0" xyz="0 0 -0.105" />
            <geometry>
                <cylinder length="0.18" radius="0.025" />
            </geometry>
        </collision>
        <visual name="arm_visual">
            <origin rpy="0 0 0" xyz="0 0 -0.105" />
            <geometry>
                <cylinder length="0.18" radius="0.025" />
            </geometry>
        </visual>
    </link>
    <joint name="arm_ud2_arm_ud3_joint" type="revolute">
        <parent link="arm_ud2" />
        <child link="arm_ud3" />
        <origin rpy="0 0 0" xyz="0 0 -0.21" />
        <axis xyz="0 -1 0" />
        <limit effort="10.0" lower="-2.8" upper="2.8" velocity="2.0" />
    </joint>
    <link name="arm_ud3">

        <inertial>
            <mass value="0.01" />
            <origin rpy="0 0 0" xyz="0 0 0" />
            <inertia ixx="0" ixy="0" ixz="0" iyy="0" iyz="0" izz="0" />
        </inertial>

        <collision>
            <origin rpy="1.57079 0 0" xyz="0 0 0" />
            <geometry>
                <cylinder length="0.06" radius="0.03" />
            </geometry>
        </collision>
        <visual>
            <origin rpy="1.57079 0 0" xyz="0 0 0" />
            <geometry>
                <cylinder length="0.06" radius="0.03" />
            </geometry>
        </visual>
        <collision name="arm_collision">
            <origin rpy="0 0 0" xyz="0 0 -0.095" />
            <geometry>
                <cylinder length="0.16" radius="0.025" />
            </geometry>
        </collision>
        <visual name="arm_visual">
            <origin rpy="0 0 0" xyz="0 0 -0.095" />
            <geometry>
                <cylinder length="0.16" radius="0.025" />
            </geometry>
        </visual>
    </link>
    <joint name="arm_ud3_arm_wrist_joint" type="revolute">
        <parent link="arm_ud3" />
        <child link="arm_wrist" />
        <origin rpy="0 0 0" xyz="0 0 -0.19" />
        <axis xyz="0 0 1" />
        <limit effort="10.0" lower="-3.14" upper="3.14" velocity="1.0" />
    </joint>
    <link name="arm_wrist">

        <inertial>
            <mass value="0.01" />
            <origin rpy="0 0 0" xyz="0 0 0" />
            <inertia ixx="0" ixy="0" ixz="0" iyy="0" iyz="0" izz="0" />
        </inertial>

        <collision>
            <origin rpy="0 0 0" xyz="0 0 0" />
            <geometry>
                <box size="0.05 0.2 0.03" />
            </geometry>
        </collision>
        <visual>
            <origin rpy="0 0 0" xyz="0 0 0" />
            <geometry>
                <box size="0.05 0.2 0.03" />
            </geometry>
        </visual>
    </link>
    <joint name="arm_wrist_gripper_left_joint" type="prismatic">
        <parent link="arm_wrist" />
        <child link="gripper_left" />
        <origin rpy="0 0 0" xyz="0 0.005 -0.065" />
        <axis xyz="0 1 0" />
        <limit effort="10.0" lower="0" upper="0.085" velocity="1.0" />
    </joint>
    <link name="gripper_left">

        <inertial>
            <mass value="0.01" />
            <origin rpy="0 0 0" xyz="0 0 0" />
            <inertia ixx="0" ixy="0" ixz="0" iyy="0" iyz="0" izz="0" />
        </inertial>

        <collision>
            <origin rpy="0 0 0" xyz="0 0 0" />
            <geometry>
                <box size="0.04 0.01 0.1" />
            </geometry>
        </collision>
        <visual>
            <origin rpy="0 0 0" xyz="0 0 0" />
            <geometry>
                <box size="0.04 0.01 0.1" />
            </geometry>
        </visual>
    </link>
    <joint name="arm_wrist_gripper_right_joint" type="prismatic">
        <parent link="arm_wrist" />
        <child link="gripper_right" />
        <origin rpy="0 0 0" xyz="0 0.005 -0.065" />
        <axis xyz="0 -1 0" />
        <limit effort="10.0" lower="0" upper="0.085" velocity="0.1" />
    </joint>
    <link name="gripper_right">

        <inertial>
            <mass value="0.01" />
            <origin rpy="0 0 0" xyz="0 0 0" />
            <inertia ixx="0" ixy="0" ixz="0" iyy="0" iyz="0" izz="0" />
        </inertial>

        <collision>
            <origin rpy="0 0 0" xyz="0 0 0" />
            <geometry>
                <box size="0.04 0.01 0.1" />
            </geometry>
        </collision>
        <visual>
            <origin rpy="0 0 0" xyz="0 0 0" />
            <geometry>
                <box size="0.04 0.01 0.1" />
            </geometry>
        </visual>
    </link>
    <joint name="arm_wrist_end_effector_joint" type="fixed">
        <parent link="arm_wrist" />
        <child link="end_effector" />
        <origin rpy="0 0 0" xyz="0 0 -0.065" />
    </joint>
    <link name="end_effector">

        <inertial>
            <mass value="0.01" />
            <origin rpy="0 0 0" xyz="0 0 0" />
            <inertia ixx="0" ixy="0" ixz="0" iyy="0" iyz="0" izz="0" />
        </inertial>

        <visual>
            <origin rpy="0 0 0" xyz="0 0 0" />
            <geometry>
                <box size="0.001 0.001 0.001" />
            </geometry>
        </visual>
    </link>
    <gazebo>
        <gripper name="kejia_gripper">
            <grasp_check>
                <attach_steps>2</attach_steps>
                <detach_steps>4</detach_steps>
                <min_contact_count>1</min_contact_count>
            </grasp_check>
            <gripper_link>gripper_left</gripper_link>
            <gripper_link>gripper_right</gripper_link>
            <palm_link>arm_wrist</palm_link>
        </gripper>
    </gazebo>
    <gazebo reference="arm_base">
        <material value="Gazebo/Green" />
    </gazebo>
    <gazebo reference="arm_ud1">
        <material value="Gazebo/Blue" />
    </gazebo>
    <gazebo reference="arm_ud2">
        <material value="Gazebo/Blue" />
    </gazebo>
    <gazebo reference="arm_ud3">
        <material value="Gazebo/Blue" />
    </gazebo>
    <gazebo reference="arm_wrist">
        <material value="Gazebo/Green" />
        <mu1>100000</mu1>
        <mu2>100000</mu2>
        <kp>100000000.0</kp>
        <kd>1.0</kd>
    </gazebo>
    <gazebo reference="gripper_right">
        <material value="Gazebo/Black" />
        <mu1>100000</mu1>
        <mu2>100000</mu2>
        <kp>100000000.0</kp>
        <kd>1.0</kd>
    </gazebo>
    <gazebo reference="gripper_left">
        <material value="Gazebo/Black" />
        <mu1>100000</mu1>
        <mu2>100000</mu2>
        <kp>100000000.0</kp>
        <kd>1.0</kd>
    </gazebo>

    <transmission name="trans_ev_support">
        <type>transmission_interface/SimpleTransmission</type>
        <actuator name="ev_support_motor">
            <hardwareInterface>hardware_interface/PositionJointInterface</hardwareInterface>
        </actuator>
        <joint name="ev_support_joint">
            <hardwareInterface>hardware_interface/PositionJointInterface</hardwareInterface>
        </joint>
    </transmission>
    <transmission name="trans_arm_base_arm_lr">
        <type>transmission_interface/SimpleTransmission</type>
        <actuator name="arm_base_arm_lr_motor">
            <hardwareInterface>hardware_interface/PositionJointInterface</hardwareInterface>
        </actuator>
        <joint name="arm_base_arm_lr_joint">
            <hardwareInterface>hardware_interface/PositionJointInterface</hardwareInterface>
        </joint>
    </transmission>
    <transmission name="trans_arm_lr_arm_ud1">
        <type>transmission_interface/SimpleTransmission</type>
        <actuator name="arm_lr_arm_ud1_motor">
            <hardwareInterface>hardware_interface/PositionJointInterface</hardwareInterface>
        </actuator>
        <joint name="arm_lr_arm_ud1_joint">
            <hardwareInterface>hardware_interface/PositionJointInterface</hardwareInterface>
        </joint>
    </transmission>
    <transmission name="trans_arm_ud1_arm_ud2">
        <type>transmission_interface/SimpleTransmission</type>
        <actuator name="arm_ud1_arm_ud2_motor">
            <hardwareInterface>hardware_interface/PositionJointInterface</hardwareInterface>
        </actuator>
        <joint name="arm_ud1_arm_ud2_joint">
            <hardwareInterface>hardware_interface/PositionJointInterface</hardwareInterface>
        </joint>
    </transmission>
    <transmission name="trans_arm_ud2_arm_ud3">
        <type>transmission_interface/SimpleTransmission</type>
        <actuator name="arm_ud2_arm_ud3_motor">
            <hardwareInterface>hardware_interface/PositionJointInterface</hardwareInterface>
        </actuator>
        <joint name="arm_ud2_arm_ud3_joint">
            <hardwareInterface>hardware_interface/PositionJointInterface</hardwareInterface>
        </joint>
    </transmission>
    <transmission name="trans_arm_ud3_arm_wrist">
        <type>transmission_interface/SimpleTransmission</type>
        <actuator name="arm_ud3_arm_wrist_motor">
            <hardwareInterface>hardware_interface/PositionJointInterface</hardwareInterface>
        </actuator>
        <joint name="arm_ud3_arm_wrist_joint">
            <hardwareInterface>hardware_interface/PositionJointInterface</hardwareInterface>
        </joint>
    </transmission>
    <transmission name="trans_arm_wrist_gripper_left">
        <type>transmission_interface/SimpleTransmission</type>
        <joint name="arm_wrist_gripper_left_joint">
            <hardwareInterface>hardware_interface/EffortJointInterface</hardwareInterface>
        </joint>
        <actuator name="arm_wrist_gripper_left_motor">
            <hardwareInterface>hardware_interface/EffortJointInterface</hardwareInterface>
            <mechanicalReduction>1</mechanicalReduction>
        </actuator>
    </transmission>
    <transmission name="trans_arm_wrist_gripper_right">
        <type>transmission_interface/SimpleTransmission</type>
        <joint name="arm_wrist_gripper_right_joint">
            <hardwareInterface>hardware_interface/EffortJointInterface</hardwareInterface>
        </joint>
        <actuator name="arm_wrist_gripper_right_motor">
            <hardwareInterface>hardware_interface/EffortJointInterface</hardwareInterface>
            <mechanicalReduction>1</mechanicalReduction>
        </actuator>
    </transmission>
    <transmission name="trans_neck_pan">
        <type>transmission_interface/SimpleTransmission</type>
        <actuator name="neck_pan_motor">
            <hardwareInterface>hardware_interface/PositionJointInterface</hardwareInterface>
        </actuator>
        <joint name="neck_pan_joint">
            <hardwareInterface>hardware_interface/PositionJointInterface</hardwareInterface>
        </joint>
    </transmission>
    <transmission name="trans_neck_tilt">
        <type>transmission_interface/SimpleTransmission</type>
        <actuator name="neck_tilt_motor">
            <hardwareInterface>hardware_interface/PositionJointInterface</hardwareInterface>
        </actuator>
        <joint name="neck_tilt_joint">
            <hardwareInterface>hardware_interface/PositionJointInterface</hardwareInterface>
        </joint>
    </transmission>
    <gazebo>
        <plugin filename="libgazebo_ros_control.so" name="gazebo_ros_control">
            <robotNamespace>/</robotNamespace>
            <robotSimType>gazebo_ros_control/DefaultRobotHWSim</robotSimType>
            <legacyModeNS>true</legacyModeNS>
        </plugin>
    </gazebo>
    <!-- Differential drive controller  -->
    <gazebo>
        <plugin filename="libgazebo_ros_diff_drive.so" name="differential_drive_controller_front">
            <leftJoint>left_wheel_joint</leftJoint>
            <rightJoint>right_wheel_joint</rightJoint>
            <wheelSeparation>0.4</wheelSeparation>
            <wheelDiameter>0.18</wheelDiameter>
            <wheelTorque>50</wheelTorque>
            <alwaysOn>true</alwaysOn>
            <updateRate>41</updateRate>
            <commandTopic>/cmd_vel</commandTopic>
            <odometryTopic>/odom</odometryTopic>
            <odometryFrame>/odom</odometryFrame>
            <odometryRate>30.0</odometryRate>
            <robotBaseFrame>/base_link</robotBaseFrame>
            <legacyMode>false</legacyMode>
        </plugin>
    </gazebo>
</robot>