<?xml version="1.0"?>
<robot xmlns:xacro="http://ros.org/wiki/xacro">
  <xacro:property name="M_PI" value="3.1415926535897931" />

  <xacro:macro name="wheel" params="name parent xyz rpy radius length meshes">

    <!-- Wheel -->
    <joint name="${name}_wheel_joint" type="continuous">
      <origin xyz="${xyz}" rpy="${rpy}"/>
      <parent link="${parent}"/>
      <child link="${name}_wheel"/>
      <axis xyz="0 0 -1"/>
      <limit effort="100" velocity="10.0"/>
      <joint_properties damping="0.0" friction="0.0"/>
    </joint>
    <link name="${name}_wheel">
      <visual name="${name}_wheel_visual">
        <origin xyz="0 0 0" rpy="0 0 0"/>
        <geometry name="{name}_wheel_geometry">
          <cylinder radius="${radius}" length="${length}"/>
        </geometry>
        <material name="orange"/>
      </visual>
      <collision>
        <origin xyz="0 0 0" rpy="0 0 0"/>
        <geometry>
          <cylinder radius="${radius}" length="${length}"/>
        </geometry>
      </collision>
      <inertial>
        <mass value="5"/>
        <origin xyz="0 0 0"/>
        <inertia ixx="0.4" ixy="0" ixz="0" iyy="0.4" iyz="0" izz="0.2"/>
      </inertial>
    </link>
    <gazebo reference="${name}_wheel">
      <!-- <mu1 value="1.0"/>
    <mu2 value="1.0"/>
    <kp value="10000000.0"/>
    <kd value="1.0"/> -->
      <mu1>100000</mu1>
      <mu2>100000</mu2>
      <kp>100000000.0</kp>
      <kd>1.0</kd>
      <fdir1 value="0 0 1"/>
      <material>Gazebo/Grey</material>
      <turnGravityOff>false</turnGravityOff>
    </gazebo>

  </xacro:macro>

</robot>
