<?xml version="1.0"?>
<sdf version="1.4">
  <model name="washmachine">
    <static>false</static>

    <link name="body">
      <inertial>
        <mass>40</mass>
        <inertia>
          <ixx>0.58</ixx>
          <ixy>0</ixy>
          <ixz>0</ixz>
          <iyy>0.58</iyy>
          <iyz>0</iyz>
          <izz>0.19</izz>
        </inertia>
      </inertial>

      <visual name="visual">
<pose>0.002 0.005 0 0 0 0</pose>
        <geometry>
          <mesh>
            <uri>model://washmachine/meshes/washmachine_body.dae</uri>

          </mesh>
        </geometry>

      </visual>

      <collision name="body_1">
<pose>0 0 0.100 0 0 0</pose>
        <geometry>
<box><size>0.6858474 0.757  0.20</size></box>
        </geometry>

      </collision>
      <visual name="body_bottem">
<pose>0 0.0455 0.075 0 0 0</pose>
        <geometry>
<box><size>0.684 0.6645  0.15</size></box>
        </geometry>

      </visual>

      <visual name="body_2">
<pose>0.317 0.0455 0.473385 0 0 0</pose>
        <geometry>
<box><size>0.05 0.6645  0.94677</size></box>
        </geometry>

      </visual>

      <visual name="body_3">
<pose>-0.317 0.0455 0.473385 0 0 0</pose>
        <geometry>
<box><size>0.05 0.6645 0.94677</size></box>
        </geometry>

      </visual>

      <collision name="body_4">
<pose>0.317 0.0455 0.473385 0 0 0</pose>
        <geometry>
<box><size>0.05 0.6645  0.94677</size></box>
        </geometry>

      </collision>

      <collision name="body_5">
<pose>-0.317 0.0455 0.473385 0 0 0</pose>
        <geometry>
<box><size>0.05 0.6645 0.94677</size></box>
        </geometry>

      </collision>

      <collision name="body_6">
<pose>0 0.354 0.473385 0 0 0</pose>
        <geometry>
<box><size>0.684 0.05 0.94677</size></box>
        </geometry>

      </collision>

      <visual name="body_back">
<pose>0 0.354 0.473385 0 0 0</pose>
        <geometry>
<box><size>0.684 0.048 0.94677</size></box>
        </geometry>

      </visual>

      <visual name="body_7">
<pose>0 0.0455 0.8671641 0 0 0</pose>
        <geometry>
<box><size>0.684 0.6645 0.158</size></box>
        </geometry>

      </visual>

      <collision name="body_8">
<pose>0 0.0455 0.8671641 0 0 0</pose>
        <geometry>
<box><size>0.684 0.6645 0.158</size></box>
        </geometry>

      </collision>
    </link>

<link name="door">
      <inertial>
        <mass>0.4</mass>
        <inertia>
          <ixx>1</ixx>
          <ixy>0</ixy>
          <ixz>0</ixz>
          <iyy>1</iyy>
          <iyz>0</iyz>
          <izz>1</izz>
        </inertia>
      </inertial>

<pose>0 -0.40 0.32 -0.1 0 0</pose>
      <visual name="door_1">
<pose>0 0 0 0 0 0</pose>
        <geometry>
          <mesh>
            <uri>model://washmachine/meshes/washmachine_door.dae</uri>
<scale>1 0.6 1</scale>
          </mesh>
        </geometry>

      </visual>

      <collision name="door_2">
<pose>0 0 0.2435 1.5708 0 0</pose>
        <geometry>
            <cylinder>
              <radius>.2435</radius>
              <length>.025</length>
            </cylinder>
        </geometry>

      </collision>
</link>

      <joint type="revolute" name="door_joint">
        <pose>-0.26 0 0 0 0 0</pose>
        <child>door</child>
        <parent>body</parent>
        <axis>
    		<limit>
      			<upper>0.0</upper>
      			<lower>-2</lower>
    		</limit>
          <xyz>0 0.1 1</xyz>
          <dynamics>
            <damping>10</damping>
          </dynamics>
        </axis>
      </joint>

  </model>
</sdf>
